[2025-03-31T12:08:43.525+0000] {taskinstance.py:1083} INFO - Dependencies all met for <TaskInstance: data_ingestion_pipeline.ingest_raw_data scheduled__2023-03-03T00:00:00+00:00 [queued]>
[2025-03-31T12:08:43.529+0000] {taskinstance.py:1083} INFO - Dependencies all met for <TaskInstance: data_ingestion_pipeline.ingest_raw_data scheduled__2023-03-03T00:00:00+00:00 [queued]>
[2025-03-31T12:08:43.530+0000] {taskinstance.py:1279} INFO - 
--------------------------------------------------------------------------------
[2025-03-31T12:08:43.530+0000] {taskinstance.py:1280} INFO - Starting attempt 1 of 1
[2025-03-31T12:08:43.530+0000] {taskinstance.py:1281} INFO - 
--------------------------------------------------------------------------------
[2025-03-31T12:08:43.536+0000] {taskinstance.py:1300} INFO - Executing <Task(PythonOperator): ingest_raw_data> on 2023-03-03 00:00:00+00:00
[2025-03-31T12:08:43.539+0000] {standard_task_runner.py:55} INFO - Started process 843 to run task
[2025-03-31T12:08:43.541+0000] {standard_task_runner.py:82} INFO - Running: ['airflow', 'tasks', 'run', 'data_ingestion_pipeline', 'ingest_raw_data', 'scheduled__2023-03-03T00:00:00+00:00', '--job-id', '63', '--raw', '--subdir', 'DAGS_FOLDER/data_pipeline.py', '--cfg-path', '/tmp/tmpwhzablr8']
[2025-03-31T12:08:43.541+0000] {standard_task_runner.py:83} INFO - Job 63: Subtask ingest_raw_data
[2025-03-31T12:08:43.645+0000] {task_command.py:388} INFO - Running <TaskInstance: data_ingestion_pipeline.ingest_raw_data scheduled__2023-03-03T00:00:00+00:00 [running]> on host ab19a3cb7e10
[2025-03-31T12:08:43.678+0000] {taskinstance.py:1509} INFO - Exporting the following env vars:
AIRFLOW_CTX_DAG_OWNER=airflow
AIRFLOW_CTX_DAG_ID=data_ingestion_pipeline
AIRFLOW_CTX_TASK_ID=ingest_raw_data
AIRFLOW_CTX_EXECUTION_DATE=2023-03-03T00:00:00+00:00
AIRFLOW_CTX_TRY_NUMBER=1
AIRFLOW_CTX_DAG_RUN_ID=scheduled__2023-03-03T00:00:00+00:00
[2025-03-31T12:08:43.682+0000] {taskinstance.py:1768} ERROR - Task failed with exception
Traceback (most recent call last):
  File "/home/airflow/.local/lib/python3.7/site-packages/pandas/io/sql.py", line 2056, in execute
    cur.execute(*args, **kwargs)
psycopg2.errors.UndefinedTable: relation "sqlite_master" does not exist
LINE 1: SELECT name FROM sqlite_master WHERE type='table' AND name=?...
                         ^


The above exception was the direct cause of the following exception:

Traceback (most recent call last):
  File "/home/airflow/.local/lib/python3.7/site-packages/airflow/operators/python.py", line 175, in execute
    return_value = self.execute_callable()
  File "/home/airflow/.local/lib/python3.7/site-packages/airflow/operators/python.py", line 192, in execute_callable
    return self.python_callable(*self.op_args, **self.op_kwargs)
  File "/opt/airflow/dags/data_pipeline.py", line 22, in ingest_raw_data
    df.to_sql('raw_sales', conn, if_exists='append', index=False)
  File "/home/airflow/.local/lib/python3.7/site-packages/pandas/core/generic.py", line 2882, in to_sql
    method=method,
  File "/home/airflow/.local/lib/python3.7/site-packages/pandas/io/sql.py", line 728, in to_sql
    **engine_kwargs,
  File "/home/airflow/.local/lib/python3.7/site-packages/pandas/io/sql.py", line 2225, in to_sql
    table.create()
  File "/home/airflow/.local/lib/python3.7/site-packages/pandas/io/sql.py", line 856, in create
    if self.exists():
  File "/home/airflow/.local/lib/python3.7/site-packages/pandas/io/sql.py", line 840, in exists
    return self.pd_sql.has_table(self.name, self.schema)
  File "/home/airflow/.local/lib/python3.7/site-packages/pandas/io/sql.py", line 2236, in has_table
    return len(self.execute(query, [name]).fetchall()) > 0
  File "/home/airflow/.local/lib/python3.7/site-packages/pandas/io/sql.py", line 2068, in execute
    raise ex from exc
pandas.io.sql.DatabaseError: Execution failed on sql 'SELECT name FROM sqlite_master WHERE type='table' AND name=?;': relation "sqlite_master" does not exist
LINE 1: SELECT name FROM sqlite_master WHERE type='table' AND name=?...
                         ^

[2025-03-31T12:08:43.687+0000] {taskinstance.py:1323} INFO - Marking task as FAILED. dag_id=data_ingestion_pipeline, task_id=ingest_raw_data, execution_date=20230303T000000, start_date=20250331T120843, end_date=20250331T120843
[2025-03-31T12:08:43.692+0000] {standard_task_runner.py:105} ERROR - Failed to execute job 63 for task ingest_raw_data (Execution failed on sql 'SELECT name FROM sqlite_master WHERE type='table' AND name=?;': relation "sqlite_master" does not exist
LINE 1: SELECT name FROM sqlite_master WHERE type='table' AND name=?...
                         ^
; 843)
[2025-03-31T12:08:43.725+0000] {local_task_job.py:208} INFO - Task exited with return code 1
[2025-03-31T12:08:43.736+0000] {taskinstance.py:2578} INFO - 0 downstream tasks scheduled from follow-on schedule check
[2025-03-31T12:35:35.159+0000] {taskinstance.py:1083} INFO - Dependencies all met for <TaskInstance: data_ingestion_pipeline.ingest_raw_data scheduled__2023-03-03T00:00:00+00:00 [queued]>
[2025-03-31T12:35:35.164+0000] {taskinstance.py:1083} INFO - Dependencies all met for <TaskInstance: data_ingestion_pipeline.ingest_raw_data scheduled__2023-03-03T00:00:00+00:00 [queued]>
[2025-03-31T12:35:35.164+0000] {taskinstance.py:1279} INFO - 
--------------------------------------------------------------------------------
[2025-03-31T12:35:35.165+0000] {taskinstance.py:1280} INFO - Starting attempt 1 of 1
[2025-03-31T12:35:35.165+0000] {taskinstance.py:1281} INFO - 
--------------------------------------------------------------------------------
[2025-03-31T12:35:35.172+0000] {taskinstance.py:1300} INFO - Executing <Task(PythonOperator): ingest_raw_data> on 2023-03-03 00:00:00+00:00
[2025-03-31T12:35:35.175+0000] {standard_task_runner.py:55} INFO - Started process 860 to run task
[2025-03-31T12:35:35.177+0000] {standard_task_runner.py:82} INFO - Running: ['airflow', 'tasks', 'run', 'data_ingestion_pipeline', 'ingest_raw_data', 'scheduled__2023-03-03T00:00:00+00:00', '--job-id', '64', '--raw', '--subdir', 'DAGS_FOLDER/data_pipeline.py', '--cfg-path', '/tmp/tmpgayuil0_']
[2025-03-31T12:35:35.178+0000] {standard_task_runner.py:83} INFO - Job 64: Subtask ingest_raw_data
[2025-03-31T12:35:35.211+0000] {task_command.py:388} INFO - Running <TaskInstance: data_ingestion_pipeline.ingest_raw_data scheduled__2023-03-03T00:00:00+00:00 [running]> on host 5504c6a7fee6
[2025-03-31T12:35:35.316+0000] {taskinstance.py:1509} INFO - Exporting the following env vars:
AIRFLOW_CTX_DAG_OWNER=airflow
AIRFLOW_CTX_DAG_ID=data_ingestion_pipeline
AIRFLOW_CTX_TASK_ID=ingest_raw_data
AIRFLOW_CTX_EXECUTION_DATE=2023-03-03T00:00:00+00:00
AIRFLOW_CTX_TRY_NUMBER=1
AIRFLOW_CTX_DAG_RUN_ID=scheduled__2023-03-03T00:00:00+00:00
[2025-03-31T12:35:35.321+0000] {taskinstance.py:1768} ERROR - Task failed with exception
Traceback (most recent call last):
  File "/home/airflow/.local/lib/python3.7/site-packages/pandas/io/sql.py", line 2056, in execute
    cur.execute(*args, **kwargs)
psycopg2.errors.UndefinedTable: relation "sqlite_master" does not exist
LINE 1: SELECT name FROM sqlite_master WHERE type='table' AND name=?...
                         ^


The above exception was the direct cause of the following exception:

Traceback (most recent call last):
  File "/home/airflow/.local/lib/python3.7/site-packages/airflow/operators/python.py", line 175, in execute
    return_value = self.execute_callable()
  File "/home/airflow/.local/lib/python3.7/site-packages/airflow/operators/python.py", line 192, in execute_callable
    return self.python_callable(*self.op_args, **self.op_kwargs)
  File "/opt/airflow/dags/data_pipeline.py", line 22, in ingest_raw_data
    df.to_sql('raw_sales', conn, if_exists='append', index=False)
  File "/home/airflow/.local/lib/python3.7/site-packages/pandas/core/generic.py", line 2882, in to_sql
    method=method,
  File "/home/airflow/.local/lib/python3.7/site-packages/pandas/io/sql.py", line 728, in to_sql
    **engine_kwargs,
  File "/home/airflow/.local/lib/python3.7/site-packages/pandas/io/sql.py", line 2225, in to_sql
    table.create()
  File "/home/airflow/.local/lib/python3.7/site-packages/pandas/io/sql.py", line 856, in create
    if self.exists():
  File "/home/airflow/.local/lib/python3.7/site-packages/pandas/io/sql.py", line 840, in exists
    return self.pd_sql.has_table(self.name, self.schema)
  File "/home/airflow/.local/lib/python3.7/site-packages/pandas/io/sql.py", line 2236, in has_table
    return len(self.execute(query, [name]).fetchall()) > 0
  File "/home/airflow/.local/lib/python3.7/site-packages/pandas/io/sql.py", line 2068, in execute
    raise ex from exc
pandas.io.sql.DatabaseError: Execution failed on sql 'SELECT name FROM sqlite_master WHERE type='table' AND name=?;': relation "sqlite_master" does not exist
LINE 1: SELECT name FROM sqlite_master WHERE type='table' AND name=?...
                         ^

[2025-03-31T12:35:35.327+0000] {taskinstance.py:1323} INFO - Marking task as FAILED. dag_id=data_ingestion_pipeline, task_id=ingest_raw_data, execution_date=20230303T000000, start_date=20250331T123535, end_date=20250331T123535
[2025-03-31T12:35:35.334+0000] {standard_task_runner.py:105} ERROR - Failed to execute job 64 for task ingest_raw_data (Execution failed on sql 'SELECT name FROM sqlite_master WHERE type='table' AND name=?;': relation "sqlite_master" does not exist
LINE 1: SELECT name FROM sqlite_master WHERE type='table' AND name=?...
                         ^
; 860)
[2025-03-31T12:35:35.363+0000] {local_task_job.py:208} INFO - Task exited with return code 1
[2025-03-31T12:35:35.375+0000] {taskinstance.py:2578} INFO - 0 downstream tasks scheduled from follow-on schedule check
