[2025-03-31T12:00:03.675+0000] {taskinstance.py:1083} INFO - Dependencies all met for <TaskInstance: data_quality_pipeline.run_dq_checks scheduled__2023-01-01T00:00:00+00:00 [queued]>
[2025-03-31T12:00:03.682+0000] {taskinstance.py:1083} INFO - Dependencies all met for <TaskInstance: data_quality_pipeline.run_dq_checks scheduled__2023-01-01T00:00:00+00:00 [queued]>
[2025-03-31T12:00:03.682+0000] {taskinstance.py:1279} INFO - 
--------------------------------------------------------------------------------
[2025-03-31T12:00:03.682+0000] {taskinstance.py:1280} INFO - Starting attempt 1 of 1
[2025-03-31T12:00:03.682+0000] {taskinstance.py:1281} INFO - 
--------------------------------------------------------------------------------
[2025-03-31T12:00:03.689+0000] {taskinstance.py:1300} INFO - Executing <Task(PythonOperator): run_dq_checks> on 2023-01-01 00:00:00+00:00
[2025-03-31T12:00:03.692+0000] {standard_task_runner.py:55} INFO - Started process 370 to run task
[2025-03-31T12:00:03.695+0000] {standard_task_runner.py:82} INFO - Running: ['airflow', 'tasks', 'run', 'data_quality_pipeline', 'run_dq_checks', 'scheduled__2023-01-01T00:00:00+00:00', '--job-id', '10', '--raw', '--subdir', 'DAGS_FOLDER/dq_pipeline.py', '--cfg-path', '/tmp/tmprxisj8xk']
[2025-03-31T12:00:03.695+0000] {standard_task_runner.py:83} INFO - Job 10: Subtask run_dq_checks
[2025-03-31T12:00:03.732+0000] {task_command.py:388} INFO - Running <TaskInstance: data_quality_pipeline.run_dq_checks scheduled__2023-01-01T00:00:00+00:00 [running]> on host 1d0e81057fe9
[2025-03-31T12:00:03.777+0000] {taskinstance.py:1509} INFO - Exporting the following env vars:
AIRFLOW_CTX_DAG_OWNER=airflow
AIRFLOW_CTX_DAG_ID=data_quality_pipeline
AIRFLOW_CTX_TASK_ID=run_dq_checks
AIRFLOW_CTX_EXECUTION_DATE=2023-01-01T00:00:00+00:00
AIRFLOW_CTX_TRY_NUMBER=1
AIRFLOW_CTX_DAG_RUN_ID=scheduled__2023-01-01T00:00:00+00:00
[2025-03-31T12:00:03.779+0000] {util.py:2007} INFO - Could not find local context root directory
[2025-03-31T12:00:03.780+0000] {base.py:2134} INFO - Created temporary directory '/tmp/tmp1tp4wign' for ephemeral docs site
[2025-03-31T12:00:03.781+0000] {abstract_data_context.py:5575} INFO - EphemeralDataContext has not implemented `_load_fluent_config()` returning empty `GxConfig`
[2025-03-31T12:00:03.781+0000] {config.py:185} INFO - Loading 'datasources' ->
[]
[2025-03-31T12:00:03.797+0000] {taskinstance.py:1768} ERROR - Task failed with exception
Traceback (most recent call last):
  File "/home/airflow/.local/lib/python3.7/site-packages/great_expectations/data_context/store/in_memory_store_backend.py", line 51, in _get
    return self._store[key]
KeyError: ('sales_data_checkpoint',)

During handling of the above exception, another exception occurred:

Traceback (most recent call last):
  File "/home/airflow/.local/lib/python3.7/site-packages/great_expectations/data_context/store/checkpoint_store.py", line 145, in get_checkpoint
    checkpoint_config: Optional[Any] = self.get(key=key)
  File "/home/airflow/.local/lib/python3.7/site-packages/great_expectations/data_context/store/store.py", line 188, in get
    value = self._store_backend.get(self.key_to_tuple(key))
  File "/home/airflow/.local/lib/python3.7/site-packages/great_expectations/data_context/store/_store_backend.py", line 121, in get
    value = self._get(key, **kwargs)
  File "/home/airflow/.local/lib/python3.7/site-packages/great_expectations/data_context/store/in_memory_store_backend.py", line 53, in _get
    raise InvalidKeyError(f"{str(e)}")
great_expectations.exceptions.exceptions.InvalidKeyError: ('sales_data_checkpoint',)

During handling of the above exception, another exception occurred:

Traceback (most recent call last):
  File "/home/airflow/.local/lib/python3.7/site-packages/airflow/operators/python.py", line 175, in execute
    return_value = self.execute_callable()
  File "/home/airflow/.local/lib/python3.7/site-packages/airflow/operators/python.py", line 192, in execute_callable
    return self.python_callable(*self.op_args, **self.op_kwargs)
  File "/opt/airflow/dags/dq_pipeline.py", line 41, in run_data_quality_checks
    checkpoint_name="sales_data_checkpoint"
  File "/home/airflow/.local/lib/python3.7/site-packages/great_expectations/core/usage_statistics/usage_statistics.py", line 318, in usage_statistics_wrapped_method
    result = func(*args, **kwargs)
  File "/home/airflow/.local/lib/python3.7/site-packages/great_expectations/data_context/data_context/abstract_data_context.py", line 2288, in run_checkpoint
    **kwargs,
  File "/home/airflow/.local/lib/python3.7/site-packages/great_expectations/data_context/data_context/abstract_data_context.py", line 2313, in _run_checkpoint
    id=id,
  File "/home/airflow/.local/lib/python3.7/site-packages/great_expectations/data_context/data_context/abstract_data_context.py", line 2163, in get_checkpoint
    name=name, id=id
  File "/home/airflow/.local/lib/python3.7/site-packages/great_expectations/data_context/store/checkpoint_store.py", line 151, in get_checkpoint
    message=f'Non-existent Checkpoint configuration named "{key.configuration_key}".\n\nDetails: {exc_ik}'  # type: ignore[union-attr]
great_expectations.exceptions.exceptions.CheckpointNotFoundError: Non-existent Checkpoint configuration named "sales_data_checkpoint".

Details: ('sales_data_checkpoint',)
[2025-03-31T12:00:03.807+0000] {taskinstance.py:1323} INFO - Marking task as FAILED. dag_id=data_quality_pipeline, task_id=run_dq_checks, execution_date=20230101T000000, start_date=20250331T120003, end_date=20250331T120003
[2025-03-31T12:00:03.813+0000] {standard_task_runner.py:105} ERROR - Failed to execute job 10 for task run_dq_checks (Non-existent Checkpoint configuration named "sales_data_checkpoint".

Details: ('sales_data_checkpoint',); 370)
[2025-03-31T12:00:03.835+0000] {local_task_job.py:208} INFO - Task exited with return code 1
[2025-03-31T12:00:03.849+0000] {taskinstance.py:2578} INFO - 0 downstream tasks scheduled from follow-on schedule check
[2025-03-31T12:12:07.695+0000] {taskinstance.py:1083} INFO - Dependencies all met for <TaskInstance: data_quality_pipeline.run_dq_checks scheduled__2023-01-01T00:00:00+00:00 [queued]>
[2025-03-31T12:12:07.701+0000] {taskinstance.py:1083} INFO - Dependencies all met for <TaskInstance: data_quality_pipeline.run_dq_checks scheduled__2023-01-01T00:00:00+00:00 [queued]>
[2025-03-31T12:12:07.702+0000] {taskinstance.py:1279} INFO - 
--------------------------------------------------------------------------------
[2025-03-31T12:12:07.702+0000] {taskinstance.py:1280} INFO - Starting attempt 1 of 1
[2025-03-31T12:12:07.702+0000] {taskinstance.py:1281} INFO - 
--------------------------------------------------------------------------------
[2025-03-31T12:12:07.709+0000] {taskinstance.py:1300} INFO - Executing <Task(PythonOperator): run_dq_checks> on 2023-01-01 00:00:00+00:00
[2025-03-31T12:12:07.713+0000] {standard_task_runner.py:55} INFO - Started process 1961 to run task
[2025-03-31T12:12:07.716+0000] {standard_task_runner.py:82} INFO - Running: ['airflow', 'tasks', 'run', 'data_quality_pipeline', 'run_dq_checks', 'scheduled__2023-01-01T00:00:00+00:00', '--job-id', '154', '--raw', '--subdir', 'DAGS_FOLDER/dq_pipeline.py', '--cfg-path', '/tmp/tmp77w7b_ta']
[2025-03-31T12:12:07.716+0000] {standard_task_runner.py:83} INFO - Job 154: Subtask run_dq_checks
[2025-03-31T12:12:07.753+0000] {task_command.py:388} INFO - Running <TaskInstance: data_quality_pipeline.run_dq_checks scheduled__2023-01-01T00:00:00+00:00 [running]> on host ab19a3cb7e10
[2025-03-31T12:12:07.795+0000] {taskinstance.py:1509} INFO - Exporting the following env vars:
AIRFLOW_CTX_DAG_OWNER=airflow
AIRFLOW_CTX_DAG_ID=data_quality_pipeline
AIRFLOW_CTX_TASK_ID=run_dq_checks
AIRFLOW_CTX_EXECUTION_DATE=2023-01-01T00:00:00+00:00
AIRFLOW_CTX_TRY_NUMBER=1
AIRFLOW_CTX_DAG_RUN_ID=scheduled__2023-01-01T00:00:00+00:00
[2025-03-31T12:12:07.796+0000] {util.py:2007} INFO - Could not find local context root directory
[2025-03-31T12:12:07.797+0000] {base.py:2134} INFO - Created temporary directory '/tmp/tmpm4mdz3sn' for ephemeral docs site
[2025-03-31T12:12:07.798+0000] {abstract_data_context.py:5575} INFO - EphemeralDataContext has not implemented `_load_fluent_config()` returning empty `GxConfig`
[2025-03-31T12:12:07.798+0000] {config.py:185} INFO - Loading 'datasources' ->
[]
[2025-03-31T12:12:07.812+0000] {taskinstance.py:1768} ERROR - Task failed with exception
Traceback (most recent call last):
  File "/home/airflow/.local/lib/python3.7/site-packages/great_expectations/data_context/store/in_memory_store_backend.py", line 51, in _get
    return self._store[key]
KeyError: ('sales_data_checkpoint',)

During handling of the above exception, another exception occurred:

Traceback (most recent call last):
  File "/home/airflow/.local/lib/python3.7/site-packages/great_expectations/data_context/store/checkpoint_store.py", line 145, in get_checkpoint
    checkpoint_config: Optional[Any] = self.get(key=key)
  File "/home/airflow/.local/lib/python3.7/site-packages/great_expectations/data_context/store/store.py", line 188, in get
    value = self._store_backend.get(self.key_to_tuple(key))
  File "/home/airflow/.local/lib/python3.7/site-packages/great_expectations/data_context/store/_store_backend.py", line 121, in get
    value = self._get(key, **kwargs)
  File "/home/airflow/.local/lib/python3.7/site-packages/great_expectations/data_context/store/in_memory_store_backend.py", line 53, in _get
    raise InvalidKeyError(f"{str(e)}")
great_expectations.exceptions.exceptions.InvalidKeyError: ('sales_data_checkpoint',)

During handling of the above exception, another exception occurred:

Traceback (most recent call last):
  File "/home/airflow/.local/lib/python3.7/site-packages/airflow/operators/python.py", line 175, in execute
    return_value = self.execute_callable()
  File "/home/airflow/.local/lib/python3.7/site-packages/airflow/operators/python.py", line 192, in execute_callable
    return self.python_callable(*self.op_args, **self.op_kwargs)
  File "/opt/airflow/dags/dq_pipeline.py", line 41, in run_data_quality_checks
    checkpoint_name="sales_data_checkpoint"
  File "/home/airflow/.local/lib/python3.7/site-packages/great_expectations/core/usage_statistics/usage_statistics.py", line 318, in usage_statistics_wrapped_method
    result = func(*args, **kwargs)
  File "/home/airflow/.local/lib/python3.7/site-packages/great_expectations/data_context/data_context/abstract_data_context.py", line 2288, in run_checkpoint
    **kwargs,
  File "/home/airflow/.local/lib/python3.7/site-packages/great_expectations/data_context/data_context/abstract_data_context.py", line 2313, in _run_checkpoint
    id=id,
  File "/home/airflow/.local/lib/python3.7/site-packages/great_expectations/data_context/data_context/abstract_data_context.py", line 2163, in get_checkpoint
    name=name, id=id
  File "/home/airflow/.local/lib/python3.7/site-packages/great_expectations/data_context/store/checkpoint_store.py", line 151, in get_checkpoint
    message=f'Non-existent Checkpoint configuration named "{key.configuration_key}".\n\nDetails: {exc_ik}'  # type: ignore[union-attr]
great_expectations.exceptions.exceptions.CheckpointNotFoundError: Non-existent Checkpoint configuration named "sales_data_checkpoint".

Details: ('sales_data_checkpoint',)
[2025-03-31T12:12:07.820+0000] {taskinstance.py:1323} INFO - Marking task as FAILED. dag_id=data_quality_pipeline, task_id=run_dq_checks, execution_date=20230101T000000, start_date=20250331T121207, end_date=20250331T121207
[2025-03-31T12:12:07.827+0000] {standard_task_runner.py:105} ERROR - Failed to execute job 154 for task run_dq_checks (Non-existent Checkpoint configuration named "sales_data_checkpoint".

Details: ('sales_data_checkpoint',); 1961)
[2025-03-31T12:12:07.859+0000] {local_task_job.py:208} INFO - Task exited with return code 1
[2025-03-31T12:12:07.873+0000] {taskinstance.py:2578} INFO - 0 downstream tasks scheduled from follow-on schedule check
[2025-03-31T12:46:54.006+0000] {taskinstance.py:1083} INFO - Dependencies all met for <TaskInstance: data_quality_pipeline.run_dq_checks scheduled__2023-01-01T00:00:00+00:00 [queued]>
[2025-03-31T12:46:54.013+0000] {taskinstance.py:1083} INFO - Dependencies all met for <TaskInstance: data_quality_pipeline.run_dq_checks scheduled__2023-01-01T00:00:00+00:00 [queued]>
[2025-03-31T12:46:54.013+0000] {taskinstance.py:1279} INFO - 
--------------------------------------------------------------------------------
[2025-03-31T12:46:54.013+0000] {taskinstance.py:1280} INFO - Starting attempt 1 of 1
[2025-03-31T12:46:54.013+0000] {taskinstance.py:1281} INFO - 
--------------------------------------------------------------------------------
[2025-03-31T12:46:54.021+0000] {taskinstance.py:1300} INFO - Executing <Task(PythonOperator): run_dq_checks> on 2023-01-01 00:00:00+00:00
[2025-03-31T12:46:54.024+0000] {standard_task_runner.py:55} INFO - Started process 152 to run task
[2025-03-31T12:46:54.029+0000] {standard_task_runner.py:82} INFO - Running: ['airflow', 'tasks', 'run', 'data_quality_pipeline', 'run_dq_checks', 'scheduled__2023-01-01T00:00:00+00:00', '--job-id', '4', '--raw', '--subdir', 'DAGS_FOLDER/dq_pipeline.py', '--cfg-path', '/tmp/tmpxx_if1pr']
[2025-03-31T12:46:54.030+0000] {standard_task_runner.py:83} INFO - Job 4: Subtask run_dq_checks
[2025-03-31T12:46:54.068+0000] {task_command.py:388} INFO - Running <TaskInstance: data_quality_pipeline.run_dq_checks scheduled__2023-01-01T00:00:00+00:00 [running]> on host 2d135a449b72
[2025-03-31T12:46:54.109+0000] {taskinstance.py:1509} INFO - Exporting the following env vars:
AIRFLOW_CTX_DAG_OWNER=airflow
AIRFLOW_CTX_DAG_ID=data_quality_pipeline
AIRFLOW_CTX_TASK_ID=run_dq_checks
AIRFLOW_CTX_EXECUTION_DATE=2023-01-01T00:00:00+00:00
AIRFLOW_CTX_TRY_NUMBER=1
AIRFLOW_CTX_DAG_RUN_ID=scheduled__2023-01-01T00:00:00+00:00
[2025-03-31T12:46:54.111+0000] {util.py:2007} INFO - Could not find local context root directory
[2025-03-31T12:46:54.112+0000] {base.py:2134} INFO - Created temporary directory '/tmp/tmpnc7mxtig' for ephemeral docs site
[2025-03-31T12:46:54.113+0000] {abstract_data_context.py:5575} INFO - EphemeralDataContext has not implemented `_load_fluent_config()` returning empty `GxConfig`
[2025-03-31T12:46:54.113+0000] {config.py:185} INFO - Loading 'datasources' ->
[]
[2025-03-31T12:46:54.129+0000] {taskinstance.py:1768} ERROR - Task failed with exception
Traceback (most recent call last):
  File "/home/airflow/.local/lib/python3.7/site-packages/great_expectations/data_context/store/in_memory_store_backend.py", line 51, in _get
    return self._store[key]
KeyError: ('sales_data_checkpoint',)

During handling of the above exception, another exception occurred:

Traceback (most recent call last):
  File "/home/airflow/.local/lib/python3.7/site-packages/great_expectations/data_context/store/checkpoint_store.py", line 145, in get_checkpoint
    checkpoint_config: Optional[Any] = self.get(key=key)
  File "/home/airflow/.local/lib/python3.7/site-packages/great_expectations/data_context/store/store.py", line 188, in get
    value = self._store_backend.get(self.key_to_tuple(key))
  File "/home/airflow/.local/lib/python3.7/site-packages/great_expectations/data_context/store/_store_backend.py", line 121, in get
    value = self._get(key, **kwargs)
  File "/home/airflow/.local/lib/python3.7/site-packages/great_expectations/data_context/store/in_memory_store_backend.py", line 53, in _get
    raise InvalidKeyError(f"{str(e)}")
great_expectations.exceptions.exceptions.InvalidKeyError: ('sales_data_checkpoint',)

During handling of the above exception, another exception occurred:

Traceback (most recent call last):
  File "/home/airflow/.local/lib/python3.7/site-packages/airflow/operators/python.py", line 175, in execute
    return_value = self.execute_callable()
  File "/home/airflow/.local/lib/python3.7/site-packages/airflow/operators/python.py", line 192, in execute_callable
    return self.python_callable(*self.op_args, **self.op_kwargs)
  File "/opt/airflow/dags/dq_pipeline.py", line 41, in run_data_quality_checks
    checkpoint_name="sales_data_checkpoint"
  File "/home/airflow/.local/lib/python3.7/site-packages/great_expectations/core/usage_statistics/usage_statistics.py", line 318, in usage_statistics_wrapped_method
    result = func(*args, **kwargs)
  File "/home/airflow/.local/lib/python3.7/site-packages/great_expectations/data_context/data_context/abstract_data_context.py", line 2288, in run_checkpoint
    **kwargs,
  File "/home/airflow/.local/lib/python3.7/site-packages/great_expectations/data_context/data_context/abstract_data_context.py", line 2313, in _run_checkpoint
    id=id,
  File "/home/airflow/.local/lib/python3.7/site-packages/great_expectations/data_context/data_context/abstract_data_context.py", line 2163, in get_checkpoint
    name=name, id=id
  File "/home/airflow/.local/lib/python3.7/site-packages/great_expectations/data_context/store/checkpoint_store.py", line 151, in get_checkpoint
    message=f'Non-existent Checkpoint configuration named "{key.configuration_key}".\n\nDetails: {exc_ik}'  # type: ignore[union-attr]
great_expectations.exceptions.exceptions.CheckpointNotFoundError: Non-existent Checkpoint configuration named "sales_data_checkpoint".

Details: ('sales_data_checkpoint',)
[2025-03-31T12:46:54.137+0000] {taskinstance.py:1323} INFO - Marking task as FAILED. dag_id=data_quality_pipeline, task_id=run_dq_checks, execution_date=20230101T000000, start_date=20250331T124654, end_date=20250331T124654
[2025-03-31T12:46:54.143+0000] {standard_task_runner.py:105} ERROR - Failed to execute job 4 for task run_dq_checks (Non-existent Checkpoint configuration named "sales_data_checkpoint".

Details: ('sales_data_checkpoint',); 152)
[2025-03-31T12:46:54.172+0000] {local_task_job.py:208} INFO - Task exited with return code 1
[2025-03-31T12:46:54.185+0000] {taskinstance.py:2578} INFO - 0 downstream tasks scheduled from follow-on schedule check
