[2025-03-31T12:28:37.911+0000] {taskinstance.py:1083} INFO - Dependencies all met for <TaskInstance: data_ingestion.ingest_raw_data scheduled__2025-03-30T00:00:00+00:00 [queued]>
[2025-03-31T12:28:37.915+0000] {taskinstance.py:1083} INFO - Dependencies all met for <TaskInstance: data_ingestion.ingest_raw_data scheduled__2025-03-30T00:00:00+00:00 [queued]>
[2025-03-31T12:28:37.915+0000] {taskinstance.py:1279} INFO - 
--------------------------------------------------------------------------------
[2025-03-31T12:28:37.915+0000] {taskinstance.py:1280} INFO - Starting attempt 1 of 2
[2025-03-31T12:28:37.915+0000] {taskinstance.py:1281} INFO - 
--------------------------------------------------------------------------------
[2025-03-31T12:28:37.922+0000] {taskinstance.py:1300} INFO - Executing <Task(PythonOperator): ingest_raw_data> on 2025-03-30 00:00:00+00:00
[2025-03-31T12:28:37.924+0000] {standard_task_runner.py:55} INFO - Started process 100 to run task
[2025-03-31T12:28:37.926+0000] {standard_task_runner.py:82} INFO - Running: ['airflow', 'tasks', 'run', 'data_ingestion', 'ingest_raw_data', 'scheduled__2025-03-30T00:00:00+00:00', '--job-id', '2', '--raw', '--subdir', 'DAGS_FOLDER/data_ingestion.py', '--cfg-path', '/tmp/tmpxv85gfwf']
[2025-03-31T12:28:37.927+0000] {standard_task_runner.py:83} INFO - Job 2: Subtask ingest_raw_data
[2025-03-31T12:28:38.079+0000] {task_command.py:388} INFO - Running <TaskInstance: data_ingestion.ingest_raw_data scheduled__2025-03-30T00:00:00+00:00 [running]> on host 7fb27947ef17
[2025-03-31T12:28:38.114+0000] {taskinstance.py:1509} INFO - Exporting the following env vars:
AIRFLOW_CTX_DAG_OWNER=airflow
AIRFLOW_CTX_DAG_ID=data_ingestion
AIRFLOW_CTX_TASK_ID=ingest_raw_data
AIRFLOW_CTX_EXECUTION_DATE=2025-03-30T00:00:00+00:00
AIRFLOW_CTX_TRY_NUMBER=1
AIRFLOW_CTX_DAG_RUN_ID=scheduled__2025-03-30T00:00:00+00:00
[2025-03-31T12:28:38.119+0000] {taskinstance.py:1768} ERROR - Task failed with exception
Traceback (most recent call last):
  File "/home/airflow/.local/lib/python3.7/site-packages/pandas/io/sql.py", line 2056, in execute
    cur.execute(*args, **kwargs)
psycopg2.errors.UndefinedTable: relation "sqlite_master" does not exist
LINE 1: SELECT name FROM sqlite_master WHERE type='table' AND name=?...
                         ^


The above exception was the direct cause of the following exception:

Traceback (most recent call last):
  File "/home/airflow/.local/lib/python3.7/site-packages/airflow/operators/python.py", line 175, in execute
    return_value = self.execute_callable()
  File "/home/airflow/.local/lib/python3.7/site-packages/airflow/operators/python.py", line 192, in execute_callable
    return self.python_callable(*self.op_args, **self.op_kwargs)
  File "/opt/airflow/dags/data_ingestion.py", line 25, in ingest_data
    df.to_sql('raw_sales', conn, if_exists='append', index=False, method='multi')
  File "/home/airflow/.local/lib/python3.7/site-packages/pandas/core/generic.py", line 2882, in to_sql
    method=method,
  File "/home/airflow/.local/lib/python3.7/site-packages/pandas/io/sql.py", line 728, in to_sql
    **engine_kwargs,
  File "/home/airflow/.local/lib/python3.7/site-packages/pandas/io/sql.py", line 2225, in to_sql
    table.create()
  File "/home/airflow/.local/lib/python3.7/site-packages/pandas/io/sql.py", line 856, in create
    if self.exists():
  File "/home/airflow/.local/lib/python3.7/site-packages/pandas/io/sql.py", line 840, in exists
    return self.pd_sql.has_table(self.name, self.schema)
  File "/home/airflow/.local/lib/python3.7/site-packages/pandas/io/sql.py", line 2236, in has_table
    return len(self.execute(query, [name]).fetchall()) > 0
  File "/home/airflow/.local/lib/python3.7/site-packages/pandas/io/sql.py", line 2068, in execute
    raise ex from exc
pandas.io.sql.DatabaseError: Execution failed on sql 'SELECT name FROM sqlite_master WHERE type='table' AND name=?;': relation "sqlite_master" does not exist
LINE 1: SELECT name FROM sqlite_master WHERE type='table' AND name=?...
                         ^

[2025-03-31T12:28:38.126+0000] {taskinstance.py:1323} INFO - Marking task as UP_FOR_RETRY. dag_id=data_ingestion, task_id=ingest_raw_data, execution_date=20250330T000000, start_date=20250331T122837, end_date=20250331T122838
[2025-03-31T12:28:38.131+0000] {standard_task_runner.py:105} ERROR - Failed to execute job 2 for task ingest_raw_data (Execution failed on sql 'SELECT name FROM sqlite_master WHERE type='table' AND name=?;': relation "sqlite_master" does not exist
LINE 1: SELECT name FROM sqlite_master WHERE type='table' AND name=?...
                         ^
; 100)
[2025-03-31T12:28:38.161+0000] {local_task_job.py:208} INFO - Task exited with return code 1
[2025-03-31T12:28:38.171+0000] {taskinstance.py:2578} INFO - 0 downstream tasks scheduled from follow-on schedule check
