[2025-03-31T12:10:07.030+0000] {taskinstance.py:1083} INFO - Dependencies all met for <TaskInstance: data_ingestion_pipeline.ingest_raw_data scheduled__2023-04-12T00:00:00+00:00 [queued]>
[2025-03-31T12:10:07.035+0000] {taskinstance.py:1083} INFO - Dependencies all met for <TaskInstance: data_ingestion_pipeline.ingest_raw_data scheduled__2023-04-12T00:00:00+00:00 [queued]>
[2025-03-31T12:10:07.035+0000] {taskinstance.py:1279} INFO - 
--------------------------------------------------------------------------------
[2025-03-31T12:10:07.035+0000] {taskinstance.py:1280} INFO - Starting attempt 1 of 1
[2025-03-31T12:10:07.035+0000] {taskinstance.py:1281} INFO - 
--------------------------------------------------------------------------------
[2025-03-31T12:10:07.042+0000] {taskinstance.py:1300} INFO - Executing <Task(PythonOperator): ingest_raw_data> on 2023-04-12 00:00:00+00:00
[2025-03-31T12:10:07.044+0000] {standard_task_runner.py:55} INFO - Started process 1333 to run task
[2025-03-31T12:10:07.046+0000] {standard_task_runner.py:82} INFO - Running: ['airflow', 'tasks', 'run', 'data_ingestion_pipeline', 'ingest_raw_data', 'scheduled__2023-04-12T00:00:00+00:00', '--job-id', '103', '--raw', '--subdir', 'DAGS_FOLDER/data_pipeline.py', '--cfg-path', '/tmp/tmpx0mvh72r']
[2025-03-31T12:10:07.047+0000] {standard_task_runner.py:83} INFO - Job 103: Subtask ingest_raw_data
[2025-03-31T12:10:07.078+0000] {task_command.py:388} INFO - Running <TaskInstance: data_ingestion_pipeline.ingest_raw_data scheduled__2023-04-12T00:00:00+00:00 [running]> on host ab19a3cb7e10
[2025-03-31T12:10:07.179+0000] {taskinstance.py:1509} INFO - Exporting the following env vars:
AIRFLOW_CTX_DAG_OWNER=airflow
AIRFLOW_CTX_DAG_ID=data_ingestion_pipeline
AIRFLOW_CTX_TASK_ID=ingest_raw_data
AIRFLOW_CTX_EXECUTION_DATE=2023-04-12T00:00:00+00:00
AIRFLOW_CTX_TRY_NUMBER=1
AIRFLOW_CTX_DAG_RUN_ID=scheduled__2023-04-12T00:00:00+00:00
[2025-03-31T12:10:07.183+0000] {taskinstance.py:1768} ERROR - Task failed with exception
Traceback (most recent call last):
  File "/home/airflow/.local/lib/python3.7/site-packages/pandas/io/sql.py", line 2056, in execute
    cur.execute(*args, **kwargs)
psycopg2.errors.UndefinedTable: relation "sqlite_master" does not exist
LINE 1: SELECT name FROM sqlite_master WHERE type='table' AND name=?...
                         ^


The above exception was the direct cause of the following exception:

Traceback (most recent call last):
  File "/home/airflow/.local/lib/python3.7/site-packages/airflow/operators/python.py", line 175, in execute
    return_value = self.execute_callable()
  File "/home/airflow/.local/lib/python3.7/site-packages/airflow/operators/python.py", line 192, in execute_callable
    return self.python_callable(*self.op_args, **self.op_kwargs)
  File "/opt/airflow/dags/data_pipeline.py", line 22, in ingest_raw_data
    df.to_sql('raw_sales', conn, if_exists='append', index=False)
  File "/home/airflow/.local/lib/python3.7/site-packages/pandas/core/generic.py", line 2882, in to_sql
    method=method,
  File "/home/airflow/.local/lib/python3.7/site-packages/pandas/io/sql.py", line 728, in to_sql
    **engine_kwargs,
  File "/home/airflow/.local/lib/python3.7/site-packages/pandas/io/sql.py", line 2225, in to_sql
    table.create()
  File "/home/airflow/.local/lib/python3.7/site-packages/pandas/io/sql.py", line 856, in create
    if self.exists():
  File "/home/airflow/.local/lib/python3.7/site-packages/pandas/io/sql.py", line 840, in exists
    return self.pd_sql.has_table(self.name, self.schema)
  File "/home/airflow/.local/lib/python3.7/site-packages/pandas/io/sql.py", line 2236, in has_table
    return len(self.execute(query, [name]).fetchall()) > 0
  File "/home/airflow/.local/lib/python3.7/site-packages/pandas/io/sql.py", line 2068, in execute
    raise ex from exc
pandas.io.sql.DatabaseError: Execution failed on sql 'SELECT name FROM sqlite_master WHERE type='table' AND name=?;': relation "sqlite_master" does not exist
LINE 1: SELECT name FROM sqlite_master WHERE type='table' AND name=?...
                         ^

[2025-03-31T12:10:07.189+0000] {taskinstance.py:1323} INFO - Marking task as FAILED. dag_id=data_ingestion_pipeline, task_id=ingest_raw_data, execution_date=20230412T000000, start_date=20250331T121007, end_date=20250331T121007
[2025-03-31T12:10:07.194+0000] {standard_task_runner.py:105} ERROR - Failed to execute job 103 for task ingest_raw_data (Execution failed on sql 'SELECT name FROM sqlite_master WHERE type='table' AND name=?;': relation "sqlite_master" does not exist
LINE 1: SELECT name FROM sqlite_master WHERE type='table' AND name=?...
                         ^
; 1333)
[2025-03-31T12:10:07.229+0000] {local_task_job.py:208} INFO - Task exited with return code 1
[2025-03-31T12:10:07.240+0000] {taskinstance.py:2578} INFO - 0 downstream tasks scheduled from follow-on schedule check
[2025-03-31T12:37:00.025+0000] {taskinstance.py:1083} INFO - Dependencies all met for <TaskInstance: data_ingestion_pipeline.ingest_raw_data scheduled__2023-04-12T00:00:00+00:00 [queued]>
[2025-03-31T12:37:00.030+0000] {taskinstance.py:1083} INFO - Dependencies all met for <TaskInstance: data_ingestion_pipeline.ingest_raw_data scheduled__2023-04-12T00:00:00+00:00 [queued]>
[2025-03-31T12:37:00.030+0000] {taskinstance.py:1279} INFO - 
--------------------------------------------------------------------------------
[2025-03-31T12:37:00.030+0000] {taskinstance.py:1280} INFO - Starting attempt 1 of 1
[2025-03-31T12:37:00.031+0000] {taskinstance.py:1281} INFO - 
--------------------------------------------------------------------------------
[2025-03-31T12:37:00.039+0000] {taskinstance.py:1300} INFO - Executing <Task(PythonOperator): ingest_raw_data> on 2023-04-12 00:00:00+00:00
[2025-03-31T12:37:00.041+0000] {standard_task_runner.py:55} INFO - Started process 1352 to run task
[2025-03-31T12:37:00.043+0000] {standard_task_runner.py:82} INFO - Running: ['airflow', 'tasks', 'run', 'data_ingestion_pipeline', 'ingest_raw_data', 'scheduled__2023-04-12T00:00:00+00:00', '--job-id', '104', '--raw', '--subdir', 'DAGS_FOLDER/data_pipeline.py', '--cfg-path', '/tmp/tmp455t2dd8']
[2025-03-31T12:37:00.044+0000] {standard_task_runner.py:83} INFO - Job 104: Subtask ingest_raw_data
[2025-03-31T12:37:00.144+0000] {task_command.py:388} INFO - Running <TaskInstance: data_ingestion_pipeline.ingest_raw_data scheduled__2023-04-12T00:00:00+00:00 [running]> on host 5504c6a7fee6
[2025-03-31T12:37:00.177+0000] {taskinstance.py:1509} INFO - Exporting the following env vars:
AIRFLOW_CTX_DAG_OWNER=airflow
AIRFLOW_CTX_DAG_ID=data_ingestion_pipeline
AIRFLOW_CTX_TASK_ID=ingest_raw_data
AIRFLOW_CTX_EXECUTION_DATE=2023-04-12T00:00:00+00:00
AIRFLOW_CTX_TRY_NUMBER=1
AIRFLOW_CTX_DAG_RUN_ID=scheduled__2023-04-12T00:00:00+00:00
[2025-03-31T12:37:00.181+0000] {taskinstance.py:1768} ERROR - Task failed with exception
Traceback (most recent call last):
  File "/home/airflow/.local/lib/python3.7/site-packages/pandas/io/sql.py", line 2056, in execute
    cur.execute(*args, **kwargs)
psycopg2.errors.UndefinedTable: relation "sqlite_master" does not exist
LINE 1: SELECT name FROM sqlite_master WHERE type='table' AND name=?...
                         ^


The above exception was the direct cause of the following exception:

Traceback (most recent call last):
  File "/home/airflow/.local/lib/python3.7/site-packages/airflow/operators/python.py", line 175, in execute
    return_value = self.execute_callable()
  File "/home/airflow/.local/lib/python3.7/site-packages/airflow/operators/python.py", line 192, in execute_callable
    return self.python_callable(*self.op_args, **self.op_kwargs)
  File "/opt/airflow/dags/data_pipeline.py", line 22, in ingest_raw_data
    df.to_sql('raw_sales', conn, if_exists='append', index=False)
  File "/home/airflow/.local/lib/python3.7/site-packages/pandas/core/generic.py", line 2882, in to_sql
    method=method,
  File "/home/airflow/.local/lib/python3.7/site-packages/pandas/io/sql.py", line 728, in to_sql
    **engine_kwargs,
  File "/home/airflow/.local/lib/python3.7/site-packages/pandas/io/sql.py", line 2225, in to_sql
    table.create()
  File "/home/airflow/.local/lib/python3.7/site-packages/pandas/io/sql.py", line 856, in create
    if self.exists():
  File "/home/airflow/.local/lib/python3.7/site-packages/pandas/io/sql.py", line 840, in exists
    return self.pd_sql.has_table(self.name, self.schema)
  File "/home/airflow/.local/lib/python3.7/site-packages/pandas/io/sql.py", line 2236, in has_table
    return len(self.execute(query, [name]).fetchall()) > 0
  File "/home/airflow/.local/lib/python3.7/site-packages/pandas/io/sql.py", line 2068, in execute
    raise ex from exc
pandas.io.sql.DatabaseError: Execution failed on sql 'SELECT name FROM sqlite_master WHERE type='table' AND name=?;': relation "sqlite_master" does not exist
LINE 1: SELECT name FROM sqlite_master WHERE type='table' AND name=?...
                         ^

[2025-03-31T12:37:00.186+0000] {taskinstance.py:1323} INFO - Marking task as FAILED. dag_id=data_ingestion_pipeline, task_id=ingest_raw_data, execution_date=20230412T000000, start_date=20250331T123700, end_date=20250331T123700
[2025-03-31T12:37:00.191+0000] {standard_task_runner.py:105} ERROR - Failed to execute job 104 for task ingest_raw_data (Execution failed on sql 'SELECT name FROM sqlite_master WHERE type='table' AND name=?;': relation "sqlite_master" does not exist
LINE 1: SELECT name FROM sqlite_master WHERE type='table' AND name=?...
                         ^
; 1352)
[2025-03-31T12:37:00.225+0000] {local_task_job.py:208} INFO - Task exited with return code 1
[2025-03-31T12:37:00.236+0000] {taskinstance.py:2578} INFO - 0 downstream tasks scheduled from follow-on schedule check
