[2025-03-31T12:01:31.888+0000] {taskinstance.py:1083} INFO - Dependencies all met for <TaskInstance: data_ingestion_pipeline.ingest_raw_data scheduled__2023-01-20T00:00:00+00:00 [queued]>
[2025-03-31T12:01:31.892+0000] {taskinstance.py:1083} INFO - Dependencies all met for <TaskInstance: data_ingestion_pipeline.ingest_raw_data scheduled__2023-01-20T00:00:00+00:00 [queued]>
[2025-03-31T12:01:31.892+0000] {taskinstance.py:1279} INFO - 
--------------------------------------------------------------------------------
[2025-03-31T12:01:31.892+0000] {taskinstance.py:1280} INFO - Starting attempt 1 of 1
[2025-03-31T12:01:31.892+0000] {taskinstance.py:1281} INFO - 
--------------------------------------------------------------------------------
[2025-03-31T12:01:31.898+0000] {taskinstance.py:1300} INFO - Executing <Task(PythonOperator): ingest_raw_data> on 2023-01-20 00:00:00+00:00
[2025-03-31T12:01:31.901+0000] {standard_task_runner.py:55} INFO - Started process 813 to run task
[2025-03-31T12:01:31.903+0000] {standard_task_runner.py:82} INFO - Running: ['airflow', 'tasks', 'run', 'data_ingestion_pipeline', 'ingest_raw_data', 'scheduled__2023-01-20T00:00:00+00:00', '--job-id', '45', '--raw', '--subdir', 'DAGS_FOLDER/data_pipeline.py', '--cfg-path', '/tmp/tmp2m81rdgi']
[2025-03-31T12:01:31.903+0000] {standard_task_runner.py:83} INFO - Job 45: Subtask ingest_raw_data
[2025-03-31T12:01:31.935+0000] {task_command.py:388} INFO - Running <TaskInstance: data_ingestion_pipeline.ingest_raw_data scheduled__2023-01-20T00:00:00+00:00 [running]> on host 1d0e81057fe9
[2025-03-31T12:01:32.036+0000] {taskinstance.py:1509} INFO - Exporting the following env vars:
AIRFLOW_CTX_DAG_OWNER=airflow
AIRFLOW_CTX_DAG_ID=data_ingestion_pipeline
AIRFLOW_CTX_TASK_ID=ingest_raw_data
AIRFLOW_CTX_EXECUTION_DATE=2023-01-20T00:00:00+00:00
AIRFLOW_CTX_TRY_NUMBER=1
AIRFLOW_CTX_DAG_RUN_ID=scheduled__2023-01-20T00:00:00+00:00
[2025-03-31T12:01:32.041+0000] {taskinstance.py:1768} ERROR - Task failed with exception
Traceback (most recent call last):
  File "/home/airflow/.local/lib/python3.7/site-packages/pandas/io/sql.py", line 2056, in execute
    cur.execute(*args, **kwargs)
psycopg2.errors.UndefinedTable: relation "sqlite_master" does not exist
LINE 1: SELECT name FROM sqlite_master WHERE type='table' AND name=?...
                         ^


The above exception was the direct cause of the following exception:

Traceback (most recent call last):
  File "/home/airflow/.local/lib/python3.7/site-packages/airflow/operators/python.py", line 175, in execute
    return_value = self.execute_callable()
  File "/home/airflow/.local/lib/python3.7/site-packages/airflow/operators/python.py", line 192, in execute_callable
    return self.python_callable(*self.op_args, **self.op_kwargs)
  File "/opt/airflow/dags/data_pipeline.py", line 22, in ingest_raw_data
    df.to_sql('raw_sales', conn, if_exists='append', index=False)
  File "/home/airflow/.local/lib/python3.7/site-packages/pandas/core/generic.py", line 2882, in to_sql
    method=method,
  File "/home/airflow/.local/lib/python3.7/site-packages/pandas/io/sql.py", line 728, in to_sql
    **engine_kwargs,
  File "/home/airflow/.local/lib/python3.7/site-packages/pandas/io/sql.py", line 2225, in to_sql
    table.create()
  File "/home/airflow/.local/lib/python3.7/site-packages/pandas/io/sql.py", line 856, in create
    if self.exists():
  File "/home/airflow/.local/lib/python3.7/site-packages/pandas/io/sql.py", line 840, in exists
    return self.pd_sql.has_table(self.name, self.schema)
  File "/home/airflow/.local/lib/python3.7/site-packages/pandas/io/sql.py", line 2236, in has_table
    return len(self.execute(query, [name]).fetchall()) > 0
  File "/home/airflow/.local/lib/python3.7/site-packages/pandas/io/sql.py", line 2068, in execute
    raise ex from exc
pandas.io.sql.DatabaseError: Execution failed on sql 'SELECT name FROM sqlite_master WHERE type='table' AND name=?;': relation "sqlite_master" does not exist
LINE 1: SELECT name FROM sqlite_master WHERE type='table' AND name=?...
                         ^

[2025-03-31T12:01:32.047+0000] {taskinstance.py:1323} INFO - Marking task as FAILED. dag_id=data_ingestion_pipeline, task_id=ingest_raw_data, execution_date=20230120T000000, start_date=20250331T120131, end_date=20250331T120132
[2025-03-31T12:01:32.052+0000] {standard_task_runner.py:105} ERROR - Failed to execute job 45 for task ingest_raw_data (Execution failed on sql 'SELECT name FROM sqlite_master WHERE type='table' AND name=?;': relation "sqlite_master" does not exist
LINE 1: SELECT name FROM sqlite_master WHERE type='table' AND name=?...
                         ^
; 813)
[2025-03-31T12:01:32.093+0000] {local_task_job.py:208} INFO - Task exited with return code 1
[2025-03-31T12:01:32.103+0000] {taskinstance.py:2578} INFO - 0 downstream tasks scheduled from follow-on schedule check
[2025-03-31T12:07:15.511+0000] {taskinstance.py:1083} INFO - Dependencies all met for <TaskInstance: data_ingestion_pipeline.ingest_raw_data scheduled__2023-01-20T00:00:00+00:00 [queued]>
[2025-03-31T12:07:15.516+0000] {taskinstance.py:1083} INFO - Dependencies all met for <TaskInstance: data_ingestion_pipeline.ingest_raw_data scheduled__2023-01-20T00:00:00+00:00 [queued]>
[2025-03-31T12:07:15.516+0000] {taskinstance.py:1279} INFO - 
--------------------------------------------------------------------------------
[2025-03-31T12:07:15.516+0000] {taskinstance.py:1280} INFO - Starting attempt 1 of 1
[2025-03-31T12:07:15.516+0000] {taskinstance.py:1281} INFO - 
--------------------------------------------------------------------------------
[2025-03-31T12:07:15.523+0000] {taskinstance.py:1300} INFO - Executing <Task(PythonOperator): ingest_raw_data> on 2023-01-20 00:00:00+00:00
[2025-03-31T12:07:15.525+0000] {standard_task_runner.py:55} INFO - Started process 327 to run task
[2025-03-31T12:07:15.527+0000] {standard_task_runner.py:82} INFO - Running: ['airflow', 'tasks', 'run', 'data_ingestion_pipeline', 'ingest_raw_data', 'scheduled__2023-01-20T00:00:00+00:00', '--job-id', '21', '--raw', '--subdir', 'DAGS_FOLDER/data_pipeline.py', '--cfg-path', '/tmp/tmpgull6kn8']
[2025-03-31T12:07:15.528+0000] {standard_task_runner.py:83} INFO - Job 21: Subtask ingest_raw_data
[2025-03-31T12:07:15.630+0000] {task_command.py:388} INFO - Running <TaskInstance: data_ingestion_pipeline.ingest_raw_data scheduled__2023-01-20T00:00:00+00:00 [running]> on host ab19a3cb7e10
[2025-03-31T12:07:15.664+0000] {taskinstance.py:1509} INFO - Exporting the following env vars:
AIRFLOW_CTX_DAG_OWNER=airflow
AIRFLOW_CTX_DAG_ID=data_ingestion_pipeline
AIRFLOW_CTX_TASK_ID=ingest_raw_data
AIRFLOW_CTX_EXECUTION_DATE=2023-01-20T00:00:00+00:00
AIRFLOW_CTX_TRY_NUMBER=1
AIRFLOW_CTX_DAG_RUN_ID=scheduled__2023-01-20T00:00:00+00:00
[2025-03-31T12:07:15.669+0000] {taskinstance.py:1768} ERROR - Task failed with exception
Traceback (most recent call last):
  File "/home/airflow/.local/lib/python3.7/site-packages/pandas/io/sql.py", line 2056, in execute
    cur.execute(*args, **kwargs)
psycopg2.errors.UndefinedTable: relation "sqlite_master" does not exist
LINE 1: SELECT name FROM sqlite_master WHERE type='table' AND name=?...
                         ^


The above exception was the direct cause of the following exception:

Traceback (most recent call last):
  File "/home/airflow/.local/lib/python3.7/site-packages/airflow/operators/python.py", line 175, in execute
    return_value = self.execute_callable()
  File "/home/airflow/.local/lib/python3.7/site-packages/airflow/operators/python.py", line 192, in execute_callable
    return self.python_callable(*self.op_args, **self.op_kwargs)
  File "/opt/airflow/dags/data_pipeline.py", line 22, in ingest_raw_data
    df.to_sql('raw_sales', conn, if_exists='append', index=False)
  File "/home/airflow/.local/lib/python3.7/site-packages/pandas/core/generic.py", line 2882, in to_sql
    method=method,
  File "/home/airflow/.local/lib/python3.7/site-packages/pandas/io/sql.py", line 728, in to_sql
    **engine_kwargs,
  File "/home/airflow/.local/lib/python3.7/site-packages/pandas/io/sql.py", line 2225, in to_sql
    table.create()
  File "/home/airflow/.local/lib/python3.7/site-packages/pandas/io/sql.py", line 856, in create
    if self.exists():
  File "/home/airflow/.local/lib/python3.7/site-packages/pandas/io/sql.py", line 840, in exists
    return self.pd_sql.has_table(self.name, self.schema)
  File "/home/airflow/.local/lib/python3.7/site-packages/pandas/io/sql.py", line 2236, in has_table
    return len(self.execute(query, [name]).fetchall()) > 0
  File "/home/airflow/.local/lib/python3.7/site-packages/pandas/io/sql.py", line 2068, in execute
    raise ex from exc
pandas.io.sql.DatabaseError: Execution failed on sql 'SELECT name FROM sqlite_master WHERE type='table' AND name=?;': relation "sqlite_master" does not exist
LINE 1: SELECT name FROM sqlite_master WHERE type='table' AND name=?...
                         ^

[2025-03-31T12:07:15.675+0000] {taskinstance.py:1323} INFO - Marking task as FAILED. dag_id=data_ingestion_pipeline, task_id=ingest_raw_data, execution_date=20230120T000000, start_date=20250331T120715, end_date=20250331T120715
[2025-03-31T12:07:15.680+0000] {standard_task_runner.py:105} ERROR - Failed to execute job 21 for task ingest_raw_data (Execution failed on sql 'SELECT name FROM sqlite_master WHERE type='table' AND name=?;': relation "sqlite_master" does not exist
LINE 1: SELECT name FROM sqlite_master WHERE type='table' AND name=?...
                         ^
; 327)
[2025-03-31T12:07:15.711+0000] {local_task_job.py:208} INFO - Task exited with return code 1
[2025-03-31T12:07:15.723+0000] {taskinstance.py:2578} INFO - 0 downstream tasks scheduled from follow-on schedule check
[2025-03-31T12:34:07.520+0000] {taskinstance.py:1083} INFO - Dependencies all met for <TaskInstance: data_ingestion_pipeline.ingest_raw_data scheduled__2023-01-20T00:00:00+00:00 [queued]>
[2025-03-31T12:34:07.525+0000] {taskinstance.py:1083} INFO - Dependencies all met for <TaskInstance: data_ingestion_pipeline.ingest_raw_data scheduled__2023-01-20T00:00:00+00:00 [queued]>
[2025-03-31T12:34:07.525+0000] {taskinstance.py:1279} INFO - 
--------------------------------------------------------------------------------
[2025-03-31T12:34:07.525+0000] {taskinstance.py:1280} INFO - Starting attempt 1 of 1
[2025-03-31T12:34:07.525+0000] {taskinstance.py:1281} INFO - 
--------------------------------------------------------------------------------
[2025-03-31T12:34:07.532+0000] {taskinstance.py:1300} INFO - Executing <Task(PythonOperator): ingest_raw_data> on 2023-01-20 00:00:00+00:00
[2025-03-31T12:34:07.534+0000] {standard_task_runner.py:55} INFO - Started process 344 to run task
[2025-03-31T12:34:07.536+0000] {standard_task_runner.py:82} INFO - Running: ['airflow', 'tasks', 'run', 'data_ingestion_pipeline', 'ingest_raw_data', 'scheduled__2023-01-20T00:00:00+00:00', '--job-id', '22', '--raw', '--subdir', 'DAGS_FOLDER/data_pipeline.py', '--cfg-path', '/tmp/tmpazkftw8u']
[2025-03-31T12:34:07.537+0000] {standard_task_runner.py:83} INFO - Job 22: Subtask ingest_raw_data
[2025-03-31T12:34:07.569+0000] {task_command.py:388} INFO - Running <TaskInstance: data_ingestion_pipeline.ingest_raw_data scheduled__2023-01-20T00:00:00+00:00 [running]> on host 5504c6a7fee6
[2025-03-31T12:34:07.666+0000] {taskinstance.py:1509} INFO - Exporting the following env vars:
AIRFLOW_CTX_DAG_OWNER=airflow
AIRFLOW_CTX_DAG_ID=data_ingestion_pipeline
AIRFLOW_CTX_TASK_ID=ingest_raw_data
AIRFLOW_CTX_EXECUTION_DATE=2023-01-20T00:00:00+00:00
AIRFLOW_CTX_TRY_NUMBER=1
AIRFLOW_CTX_DAG_RUN_ID=scheduled__2023-01-20T00:00:00+00:00
[2025-03-31T12:34:07.671+0000] {taskinstance.py:1768} ERROR - Task failed with exception
Traceback (most recent call last):
  File "/home/airflow/.local/lib/python3.7/site-packages/pandas/io/sql.py", line 2056, in execute
    cur.execute(*args, **kwargs)
psycopg2.errors.UndefinedTable: relation "sqlite_master" does not exist
LINE 1: SELECT name FROM sqlite_master WHERE type='table' AND name=?...
                         ^


The above exception was the direct cause of the following exception:

Traceback (most recent call last):
  File "/home/airflow/.local/lib/python3.7/site-packages/airflow/operators/python.py", line 175, in execute
    return_value = self.execute_callable()
  File "/home/airflow/.local/lib/python3.7/site-packages/airflow/operators/python.py", line 192, in execute_callable
    return self.python_callable(*self.op_args, **self.op_kwargs)
  File "/opt/airflow/dags/data_pipeline.py", line 22, in ingest_raw_data
    df.to_sql('raw_sales', conn, if_exists='append', index=False)
  File "/home/airflow/.local/lib/python3.7/site-packages/pandas/core/generic.py", line 2882, in to_sql
    method=method,
  File "/home/airflow/.local/lib/python3.7/site-packages/pandas/io/sql.py", line 728, in to_sql
    **engine_kwargs,
  File "/home/airflow/.local/lib/python3.7/site-packages/pandas/io/sql.py", line 2225, in to_sql
    table.create()
  File "/home/airflow/.local/lib/python3.7/site-packages/pandas/io/sql.py", line 856, in create
    if self.exists():
  File "/home/airflow/.local/lib/python3.7/site-packages/pandas/io/sql.py", line 840, in exists
    return self.pd_sql.has_table(self.name, self.schema)
  File "/home/airflow/.local/lib/python3.7/site-packages/pandas/io/sql.py", line 2236, in has_table
    return len(self.execute(query, [name]).fetchall()) > 0
  File "/home/airflow/.local/lib/python3.7/site-packages/pandas/io/sql.py", line 2068, in execute
    raise ex from exc
pandas.io.sql.DatabaseError: Execution failed on sql 'SELECT name FROM sqlite_master WHERE type='table' AND name=?;': relation "sqlite_master" does not exist
LINE 1: SELECT name FROM sqlite_master WHERE type='table' AND name=?...
                         ^

[2025-03-31T12:34:07.676+0000] {taskinstance.py:1323} INFO - Marking task as FAILED. dag_id=data_ingestion_pipeline, task_id=ingest_raw_data, execution_date=20230120T000000, start_date=20250331T123407, end_date=20250331T123407
[2025-03-31T12:34:07.681+0000] {standard_task_runner.py:105} ERROR - Failed to execute job 22 for task ingest_raw_data (Execution failed on sql 'SELECT name FROM sqlite_master WHERE type='table' AND name=?;': relation "sqlite_master" does not exist
LINE 1: SELECT name FROM sqlite_master WHERE type='table' AND name=?...
                         ^
; 344)
[2025-03-31T12:34:07.721+0000] {local_task_job.py:208} INFO - Task exited with return code 1
[2025-03-31T12:34:07.732+0000] {taskinstance.py:2578} INFO - 0 downstream tasks scheduled from follow-on schedule check
